{
    "registryname": "auto_mechanical_anvil",
    "localizedname": "AutoMechanical Anvil", 
    "requires-blueprint": false, 
    "color": "708090", 
    "parts": [
        {
            "x": -1,
            "y": 2,
            "z": 3,
            "elements": "casings_decorative"
        },
        {
            "x": -1,
            "y": 0,
            "z": 0,
            "elements": "casings_item"
        },
        {
            "x": 1,
            "y": 2,
            "z": 1,
            "elements": "casings_decorative"
        },
        {
            "x": 0,
            "y": 2,
            "z": 3,
            "elements": "casings_decorative"
        },
        {
            "x": 1,
            "y": 0,
            "z": 0,
            "elements": "casings_item"
        },
        {
            "x": -1,
            "y": 0,
            "z": 2,
            "elements": "casings_energy"
        },
        {
            "x": 0,
            "y": 0,
            "z": 2,
            "elements": [
                "pixelmon:anvil"
            ]
        },
        {
            "x": 1,
            "y": 2,
            "z": 3,
            "elements": "casings_decorative"
        },
        {
            "x": 1,
            "y": 0,
            "z": 2,
            "elements": "casings_energy"
        },
        {
            "x": -1,
            "y": 0,
            "z": 4,
            "elements": "casings_item"
        },
        {
            "x": 0,
            "y": 0,
            "z": 4,
            "elements": [
                "modularmachinery:blockcasing@1"
            ]
        },
        {
            "x": 1,
            "y": 0,
            "z": 4,
            "elements": "casings_item"
        },
        {
            "x": 1,
            "y": -1,
            "z": 0,
            "elements": "casings_decorative"
        },
        {
            "x": 0,
            "y": -1,
            "z": 0,
            "elements": "casings_decorative"
        },
        {
            "x": -1,
            "y": 1,
            "z": 0,
            "elements": "casings_decorative"
        },
        {
            "x": 0,
            "y": 1,
            "z": 0,
            "elements": "casings_decorative"
        },
        {
            "x": -1,
            "y": -1,
            "z": 0,
            "elements": "casings_decorative"
        },
        {
            "x": -1,
            "y": 1,
            "z": 2,
            "elements": [
                "modularmachinery:blockcasing@1"
            ]
        },
        {
            "x": 1,
            "y": 1,
            "z": 0,
            "elements": "casings_decorative"
        },
        {
            "x": 0,
            "y": 1,
            "z": 2,
            "elements": [
                "pixelmon:anvil"
            ]
        },
        {
            "x": -1,
            "y": -1,
            "z": 1,
            "elements": "casings_decorative"
        },
        {
            "x": 0,
            "y": -1,
            "z": 1,
            "elements": "casings_decorative"
        },
        {
            "x": -1,
            "y": 1,
            "z": 4,
            "elements": "casings_decorative"
        },
        {
            "x": 1,
            "y": 1,
            "z": 2,
            "elements": [
                "modularmachinery:blockcasing@1"
            ]
        },
        {
            "x": 0,
            "y": 1,
            "z": 4,
            "elements": "casings_decorative"
        },
        {
            "x": 1,
            "y": -1,
            "z": 1,
            "elements": "casings_decorative"
        },
        {
            "x": -1,
            "y": -1,
            "z": 3,
            "elements": "casings_decorative"
        },
        {
            "x": 0,
            "y": -1,
            "z": 3,
            "elements": "casings_decorative"
        },
        {
            "x": 1,
            "y": 1,
            "z": 4,
            "elements": "casings_decorative"
        },
        {
            "x": 1,
            "y": -1,
            "z": 3,
            "elements": "casings_decorative"
        },
        {
            "x": -1,
            "y": 2,
            "z": 0,
            "elements": "casings_decorative"
        },
        {
            "x": 0,
            "y": 2,
            "z": 0,
            "elements": "casings_decorative"
        },
        {
            "x": -1,
            "y": 2,
            "z": 2,
            "elements": "casings_decorative"
        },
        {
            "x": 1,
            "y": 2,
            "z": 0,
            "elements": "casings_decorative"
        },
        {
            "x": 0,
            "y": 2,
            "z": 2,
            "elements": "casings_decorative"
        },
        {
            "x": -1,
            "y": 0,
            "z": 1,
            "elements": [
                "modularmachinery:blockcasing@3"
            ]
        },
        {
            "x": -1,
            "y": 2,
            "z": 4,
            "elements": "casings_decorative"
        },
        {
            "x": 1,
            "y": 2,
            "z": 2,
            "elements": "casings_decorative"
        },
        {
            "x": 0,
            "y": 2,
            "z": 4,
            "elements": "casings_decorative"
        },
        {
            "x": 1,
            "y": 0,
            "z": 1,
            "elements": [
                "modularmachinery:blockcasing@3"
            ]
        },
        {
            "x": -1,
            "y": 0,
            "z": 3,
            "elements": [
                "modularmachinery:blockcasing@3"
            ]
        },
        {
            "x": 1,
            "y": 2,
            "z": 4,
            "elements": "casings_decorative"
        },
        {
            "x": 1,
            "y": 0,
            "z": 3,
            "elements": [
                "modularmachinery:blockcasing@3"
            ]
        },
        {
            "x": -1,
            "y": 1,
            "z": 1,
            "elements": "casings_decorative"
        },
        {
            "x": 0,
            "y": 1,
            "z": 1,
            "elements": [
                "pixelmon:mechanical_anvil"
            ]
        },
        {
            "x": -1,
            "y": 1,
            "z": 3,
            "elements": "casings_decorative"
        },
        {
            "x": 1,
            "y": 1,
            "z": 1,
            "elements": "casings_decorative"
        },
        {
            "x": 0,
            "y": 1,
            "z": 3,
            "elements": [
                "pixelmon:mechanical_anvil"
            ]
        },
        {
            "x": -1,
            "y": -1,
            "z": 2,
            "elements": [
                "modularmachinery:blockcasing@1"
            ]
        },
        {
            "x": 0,
            "y": -1,
            "z": 2,
            "elements": "casings_decorative"
        },
        {
            "x": 1,
            "y": 1,
            "z": 3,
            "elements": "casings_decorative"
        },
        {
            "x": 1,
            "y": -1,
            "z": 2,
            "elements": [
                "modularmachinery:blockcasing@1"
            ]
        },
        {
            "x": -1,
            "y": -1,
            "z": 4,
            "elements": "casings_decorative"
        },
        {
            "x": 0,
            "y": -1,
            "z": 4,
            "elements": "casings_decorative"
        },
        {
            "x": 1,
            "y": -1,
            "z": 4,
            "elements": "casings_decorative"
        },
        {
            "x": -1,
            "y": 2,
            "z": 1,
            "elements": "casings_decorative"
        },
        {
            "x": 0,
            "y": 2,
            "z": 1,
            "elements": "casings_decorative"
        }
    ]}